Exception in thread Exception in thread Thread-1:
Thread-1:
Traceback (most recent call last):
Traceback (most recent call last):
  File "/usr/lib/python3.8/threading.py", line 932, in _bootstrap_inner
Exception in thread   File "/usr/lib/python3.8/threading.py", line 932, in _bootstrap_inner
Thread-1:
Traceback (most recent call last):
  File "/usr/lib/python3.8/threading.py", line 932, in _bootstrap_inner
    self.run()
  File "/home/gitonga/frappe-bench/env/lib/python3.8/site-packages/redis/client.py", line 3718, in run
        self.run()self.run()

  File "/home/gitonga/frappe-bench/env/lib/python3.8/site-packages/redis/client.py", line 3718, in run
  File "/home/gitonga/frappe-bench/env/lib/python3.8/site-packages/redis/client.py", line 3718, in run
    pubsub.get_message(ignore_subscribe_messages=True,
  File "/home/gitonga/frappe-bench/env/lib/python3.8/site-packages/redis/client.py", line 3617, in get_message
    pubsub.get_message(ignore_subscribe_messages=True,
    pubsub.get_message(ignore_subscribe_messages=True,  File "/home/gitonga/frappe-bench/env/lib/python3.8/site-packages/redis/client.py", line 3617, in get_message

  File "/home/gitonga/frappe-bench/env/lib/python3.8/site-packages/redis/client.py", line 3617, in get_message
    response = self.parse_response(block=False, timeout=timeout)
  File "/home/gitonga/frappe-bench/env/lib/python3.8/site-packages/redis/client.py", line 3503, in parse_response
        response = self.parse_response(block=False, timeout=timeout)response = self.parse_response(block=False, timeout=timeout)

  File "/home/gitonga/frappe-bench/env/lib/python3.8/site-packages/redis/client.py", line 3503, in parse_response
  File "/home/gitonga/frappe-bench/env/lib/python3.8/site-packages/redis/client.py", line 3503, in parse_response
    if not block and not conn.can_read(timeout=timeout):
  File "/home/gitonga/frappe-bench/env/lib/python3.8/site-packages/redis/connection.py", line 734, in can_read
    return self._parser.can_read(timeout)
  File "/home/gitonga/frappe-bench/env/lib/python3.8/site-packages/redis/connection.py", line 321, in can_read
    return self._buffer and self._buffer.can_read(timeout)
  File "/home/gitonga/frappe-bench/env/lib/python3.8/site-packages/redis/connection.py", line 230, in can_read
    self._read_from_socket(timeout=timeout,
  File "/home/gitonga/frappe-bench/env/lib/python3.8/site-packages/redis/connection.py", line 201, in _read_from_socket
    raise ConnectionError(SERVER_CLOSED_CONNECTION_ERROR)
redis.exceptions.ConnectionError: Connection closed by server.
        if not block and not conn.can_read(timeout=timeout):if not block and not conn.can_read(timeout=timeout):

  File "/home/gitonga/frappe-bench/env/lib/python3.8/site-packages/redis/connection.py", line 734, in can_read
  File "/home/gitonga/frappe-bench/env/lib/python3.8/site-packages/redis/connection.py", line 734, in can_read
        return self._parser.can_read(timeout)return self._parser.can_read(timeout)

  File "/home/gitonga/frappe-bench/env/lib/python3.8/site-packages/redis/connection.py", line 321, in can_read
  File "/home/gitonga/frappe-bench/env/lib/python3.8/site-packages/redis/connection.py", line 321, in can_read
        return self._buffer and self._buffer.can_read(timeout)return self._buffer and self._buffer.can_read(timeout)

  File "/home/gitonga/frappe-bench/env/lib/python3.8/site-packages/redis/connection.py", line 230, in can_read
  File "/home/gitonga/frappe-bench/env/lib/python3.8/site-packages/redis/connection.py", line 230, in can_read
        self._read_from_socket(timeout=timeout,self._read_from_socket(timeout=timeout,

  File "/home/gitonga/frappe-bench/env/lib/python3.8/site-packages/redis/connection.py", line 201, in _read_from_socket
  File "/home/gitonga/frappe-bench/env/lib/python3.8/site-packages/redis/connection.py", line 201, in _read_from_socket
        raise ConnectionError(SERVER_CLOSED_CONNECTION_ERROR)raise ConnectionError(SERVER_CLOSED_CONNECTION_ERROR)

redis.exceptionsredis.exceptions..ConnectionErrorConnectionError: : Connection closed by server.Connection closed by server.

Exception in thread Exception in thread Thread-1:
Thread-1:
Traceback (most recent call last):
Traceback (most recent call last):
  File "/usr/lib/python3.8/threading.py", line 932, in _bootstrap_inner
  File "/usr/lib/python3.8/threading.py", line 932, in _bootstrap_inner
        self.run()self.run()

  File "/home/gitonga/frappe-bench/env/lib/python3.8/site-packages/redis/client.py", line 3718, in run
  File "/home/gitonga/frappe-bench/env/lib/python3.8/site-packages/redis/client.py", line 3718, in run
        pubsub.get_message(ignore_subscribe_messages=True,pubsub.get_message(ignore_subscribe_messages=True,

  File "/home/gitonga/frappe-bench/env/lib/python3.8/site-packages/redis/client.py", line 3617, in get_message
  File "/home/gitonga/frappe-bench/env/lib/python3.8/site-packages/redis/client.py", line 3617, in get_message
        response = self.parse_response(block=False, timeout=timeout)response = self.parse_response(block=False, timeout=timeout)

  File "/home/gitonga/frappe-bench/env/lib/python3.8/site-packages/redis/client.py", line 3503, in parse_response
  File "/home/gitonga/frappe-bench/env/lib/python3.8/site-packages/redis/client.py", line 3503, in parse_response
    if not block and not conn.can_read(timeout=timeout):
  File "/home/gitonga/frappe-bench/env/lib/python3.8/site-packages/redis/connection.py", line 734, in can_read
    if not block and not conn.can_read(timeout=timeout):
  File "/home/gitonga/frappe-bench/env/lib/python3.8/site-packages/redis/connection.py", line 734, in can_read
    return self._parser.can_read(timeout)
  File "/home/gitonga/frappe-bench/env/lib/python3.8/site-packages/redis/connection.py", line 321, in can_read
    return self._buffer and self._buffer.can_read(timeout)
  File "/home/gitonga/frappe-bench/env/lib/python3.8/site-packages/redis/connection.py", line 230, in can_read
    return self._parser.can_read(timeout)
  File "/home/gitonga/frappe-bench/env/lib/python3.8/site-packages/redis/connection.py", line 321, in can_read
    self._read_from_socket(timeout=timeout,
  File "/home/gitonga/frappe-bench/env/lib/python3.8/site-packages/redis/connection.py", line 201, in _read_from_socket
    return self._buffer and self._buffer.can_read(timeout)
  File "/home/gitonga/frappe-bench/env/lib/python3.8/site-packages/redis/connection.py", line 230, in can_read
    raise ConnectionError(SERVER_CLOSED_CONNECTION_ERROR)
redis.exceptions.ConnectionError: Connection closed by server.
    self._read_from_socket(timeout=timeout,
  File "/home/gitonga/frappe-bench/env/lib/python3.8/site-packages/redis/connection.py", line 201, in _read_from_socket
    raise ConnectionError(SERVER_CLOSED_CONNECTION_ERROR)
redis.exceptions.ConnectionError: Connection closed by server.
Exception in thread Exception in thread Thread-1:
Thread-1:
Traceback (most recent call last):
Traceback (most recent call last):
  File "/usr/lib/python3.8/threading.py", line 932, in _bootstrap_inner
  File "/usr/lib/python3.8/threading.py", line 932, in _bootstrap_inner
        self.run()self.run()

  File "/home/gitonga/frappe-bench/env/lib/python3.8/site-packages/redis/client.py", line 3718, in run
  File "/home/gitonga/frappe-bench/env/lib/python3.8/site-packages/redis/client.py", line 3718, in run
    pubsub.get_message(ignore_subscribe_messages=True,
  File "/home/gitonga/frappe-bench/env/lib/python3.8/site-packages/redis/client.py", line 3617, in get_message
    pubsub.get_message(ignore_subscribe_messages=True,
  File "/home/gitonga/frappe-bench/env/lib/python3.8/site-packages/redis/client.py", line 3617, in get_message
    response = self.parse_response(block=False, timeout=timeout)
  File "/home/gitonga/frappe-bench/env/lib/python3.8/site-packages/redis/client.py", line 3503, in parse_response
    response = self.parse_response(block=False, timeout=timeout)
  File "/home/gitonga/frappe-bench/env/lib/python3.8/site-packages/redis/client.py", line 3503, in parse_response
    if not block and not conn.can_read(timeout=timeout):
  File "/home/gitonga/frappe-bench/env/lib/python3.8/site-packages/redis/connection.py", line 734, in can_read
    if not block and not conn.can_read(timeout=timeout):
  File "/home/gitonga/frappe-bench/env/lib/python3.8/site-packages/redis/connection.py", line 734, in can_read
        return self._parser.can_read(timeout)return self._parser.can_read(timeout)

  File "/home/gitonga/frappe-bench/env/lib/python3.8/site-packages/redis/connection.py", line 321, in can_read
  File "/home/gitonga/frappe-bench/env/lib/python3.8/site-packages/redis/connection.py", line 321, in can_read
    return self._buffer and self._buffer.can_read(timeout)
  File "/home/gitonga/frappe-bench/env/lib/python3.8/site-packages/redis/connection.py", line 230, in can_read
    return self._buffer and self._buffer.can_read(timeout)
  File "/home/gitonga/frappe-bench/env/lib/python3.8/site-packages/redis/connection.py", line 230, in can_read
    self._read_from_socket(timeout=timeout,
  File "/home/gitonga/frappe-bench/env/lib/python3.8/site-packages/redis/connection.py", line 201, in _read_from_socket
    self._read_from_socket(timeout=timeout,
  File "/home/gitonga/frappe-bench/env/lib/python3.8/site-packages/redis/connection.py", line 201, in _read_from_socket
    raise ConnectionError(SERVER_CLOSED_CONNECTION_ERROR)
    raise ConnectionError(SERVER_CLOSED_CONNECTION_ERROR)redis.exceptions
.ConnectionError: Connection closed by server.redis.exceptions
.ConnectionError: Connection closed by server.
Exception in thread Thread-1:
Traceback (most recent call last):
  File "/usr/lib/python3.8/threading.py", line 932, in _bootstrap_inner
    self.run()
  File "/home/gitonga/frappe-bench/env/lib/python3.8/site-packages/redis/client.py", line 3718, in run
Exception in thread Thread-1:
Traceback (most recent call last):
  File "/usr/lib/python3.8/threading.py", line 932, in _bootstrap_inner
    self.run()
  File "/home/gitonga/frappe-bench/env/lib/python3.8/site-packages/redis/client.py", line 3718, in run
    pubsub.get_message(ignore_subscribe_messages=True,
  File "/home/gitonga/frappe-bench/env/lib/python3.8/site-packages/redis/client.py", line 3617, in get_message
    pubsub.get_message(ignore_subscribe_messages=True,
  File "/home/gitonga/frappe-bench/env/lib/python3.8/site-packages/redis/client.py", line 3617, in get_message
    response = self.parse_response(block=False, timeout=timeout)
  File "/home/gitonga/frappe-bench/env/lib/python3.8/site-packages/redis/client.py", line 3503, in parse_response
    if not block and not conn.can_read(timeout=timeout):
  File "/home/gitonga/frappe-bench/env/lib/python3.8/site-packages/redis/connection.py", line 734, in can_read
    response = self.parse_response(block=False, timeout=timeout)
  File "/home/gitonga/frappe-bench/env/lib/python3.8/site-packages/redis/client.py", line 3503, in parse_response
    return self._parser.can_read(timeout)
  File "/home/gitonga/frappe-bench/env/lib/python3.8/site-packages/redis/connection.py", line 321, in can_read
    return self._buffer and self._buffer.can_read(timeout)
  File "/home/gitonga/frappe-bench/env/lib/python3.8/site-packages/redis/connection.py", line 230, in can_read
    self._read_from_socket(timeout=timeout,
  File "/home/gitonga/frappe-bench/env/lib/python3.8/site-packages/redis/connection.py", line 201, in _read_from_socket
    raise ConnectionError(SERVER_CLOSED_CONNECTION_ERROR)
redis.exceptions.ConnectionError: Connection closed by server.
    if not block and not conn.can_read(timeout=timeout):
  File "/home/gitonga/frappe-bench/env/lib/python3.8/site-packages/redis/connection.py", line 734, in can_read
    return self._parser.can_read(timeout)
  File "/home/gitonga/frappe-bench/env/lib/python3.8/site-packages/redis/connection.py", line 321, in can_read
    return self._buffer and self._buffer.can_read(timeout)
  File "/home/gitonga/frappe-bench/env/lib/python3.8/site-packages/redis/connection.py", line 230, in can_read
    self._read_from_socket(timeout=timeout,
  File "/home/gitonga/frappe-bench/env/lib/python3.8/site-packages/redis/connection.py", line 201, in _read_from_socket
    raise ConnectionError(SERVER_CLOSED_CONNECTION_ERROR)
redis.exceptions.ConnectionError: Connection closed by server.
Exception in thread Thread-1:
Traceback (most recent call last):
  File "/usr/lib/python3.8/threading.py", line 932, in _bootstrap_inner
Exception in thread Thread-1:
Traceback (most recent call last):
  File "/usr/lib/python3.8/threading.py", line 932, in _bootstrap_inner
    Exception in thread self.run()
Thread-1  File "/home/gitonga/frappe-bench/env/lib/python3.8/site-packages/redis/client.py", line 3718, in run
:
Traceback (most recent call last):
  File "/usr/lib/python3.8/threading.py", line 932, in _bootstrap_inner
    self.run()
  File "/home/gitonga/frappe-bench/env/lib/python3.8/site-packages/redis/client.py", line 3718, in run
    self.run()
  File "/home/gitonga/frappe-bench/env/lib/python3.8/site-packages/redis/client.py", line 3718, in run
    pubsub.get_message(ignore_subscribe_messages=True,
  File "/home/gitonga/frappe-bench/env/lib/python3.8/site-packages/redis/client.py", line 3617, in get_message
    pubsub.get_message(ignore_subscribe_messages=True,
  File "/home/gitonga/frappe-bench/env/lib/python3.8/site-packages/redis/client.py", line 3617, in get_message
    pubsub.get_message(ignore_subscribe_messages=True,
  File "/home/gitonga/frappe-bench/env/lib/python3.8/site-packages/redis/client.py", line 3617, in get_message
    response = self.parse_response(block=False, timeout=timeout)
  File "/home/gitonga/frappe-bench/env/lib/python3.8/site-packages/redis/client.py", line 3503, in parse_response
    response = self.parse_response(block=False, timeout=timeout)
  File "/home/gitonga/frappe-bench/env/lib/python3.8/site-packages/redis/client.py", line 3503, in parse_response
    response = self.parse_response(block=False, timeout=timeout)
  File "/home/gitonga/frappe-bench/env/lib/python3.8/site-packages/redis/client.py", line 3503, in parse_response
    if not block and not conn.can_read(timeout=timeout):
  File "/home/gitonga/frappe-bench/env/lib/python3.8/site-packages/redis/connection.py", line 734, in can_read
    if not block and not conn.can_read(timeout=timeout):
      File "/home/gitonga/frappe-bench/env/lib/python3.8/site-packages/redis/connection.py", line 734, in can_read
if not block and not conn.can_read(timeout=timeout):
  File "/home/gitonga/frappe-bench/env/lib/python3.8/site-packages/redis/connection.py", line 734, in can_read
    return self._parser.can_read(timeout)
      File "/home/gitonga/frappe-bench/env/lib/python3.8/site-packages/redis/connection.py", line 321, in can_read
return self._parser.can_read(timeout)
  File "/home/gitonga/frappe-bench/env/lib/python3.8/site-packages/redis/connection.py", line 321, in can_read
    return self._buffer and self._buffer.can_read(timeout)
  File "/home/gitonga/frappe-bench/env/lib/python3.8/site-packages/redis/connection.py", line 230, in can_read
    return self._parser.can_read(timeout)
  File "/home/gitonga/frappe-bench/env/lib/python3.8/site-packages/redis/connection.py", line 321, in can_read
    return self._buffer and self._buffer.can_read(timeout)
  File "/home/gitonga/frappe-bench/env/lib/python3.8/site-packages/redis/connection.py", line 230, in can_read
    self._read_from_socket(timeout=timeout,
  File "/home/gitonga/frappe-bench/env/lib/python3.8/site-packages/redis/connection.py", line 201, in _read_from_socket
    raise ConnectionError(SERVER_CLOSED_CONNECTION_ERROR)
redis.exceptions.ConnectionError: Connection closed by server.        
return self._buffer and self._buffer.can_read(timeout)self._read_from_socket(timeout=timeout,

  File "/home/gitonga/frappe-bench/env/lib/python3.8/site-packages/redis/connection.py", line 230, in can_read
  File "/home/gitonga/frappe-bench/env/lib/python3.8/site-packages/redis/connection.py", line 201, in _read_from_socket
    raise ConnectionError(SERVER_CLOSED_CONNECTION_ERROR)
    self._read_from_socket(timeout=timeout,redis.exceptions
.ConnectionError  File "/home/gitonga/frappe-bench/env/lib/python3.8/site-packages/redis/connection.py", line 201, in _read_from_socket
: Connection closed by server.
    raise ConnectionError(SERVER_CLOSED_CONNECTION_ERROR)
redis.exceptions.ConnectionError: Connection closed by server.
Exception in thread Thread-1:
Traceback (most recent call last):
  File "/usr/lib/python3.8/threading.py", line 932, in _bootstrap_inner
    self.run()
  File "/home/gitonga/frappe-bench/env/lib/python3.8/site-packages/redis/client.py", line 3718, in run
    pubsub.get_message(ignore_subscribe_messages=True,
  File "/home/gitonga/frappe-bench/env/lib/python3.8/site-packages/redis/client.py", line 3617, in get_message
    response = self.parse_response(block=False, timeout=timeout)
  File "/home/gitonga/frappe-bench/env/lib/python3.8/site-packages/redis/client.py", line 3503, in parse_response
    if not block and not conn.can_read(timeout=timeout):
  File "/home/gitonga/frappe-bench/env/lib/python3.8/site-packages/redis/connection.py", line 734, in can_read
    return self._parser.can_read(timeout)
  File "/home/gitonga/frappe-bench/env/lib/python3.8/site-packages/redis/connection.py", line 321, in can_read
    return self._buffer and self._buffer.can_read(timeout)
  File "/home/gitonga/frappe-bench/env/lib/python3.8/site-packages/redis/connection.py", line 230, in can_read
    self._read_from_socket(timeout=timeout,
  File "/home/gitonga/frappe-bench/env/lib/python3.8/site-packages/redis/connection.py", line 201, in _read_from_socket
    raise ConnectionError(SERVER_CLOSED_CONNECTION_ERROR)
redis.exceptions.ConnectionError: Connection closed by server.
Exception in thread Thread-1:
Traceback (most recent call last):
  File "/usr/lib/python3.8/threading.py", line 932, in _bootstrap_inner
Exception in thread Thread-1:
Traceback (most recent call last):
  File "/usr/lib/python3.8/threading.py", line 932, in _bootstrap_inner
    self.run()
  File "/home/gitonga/frappe-bench/env/lib/python3.8/site-packages/redis/client.py", line 3718, in run
    self.run()
  File "/home/gitonga/frappe-bench/env/lib/python3.8/site-packages/redis/client.py", line 3718, in run
        pubsub.get_message(ignore_subscribe_messages=True,pubsub.get_message(ignore_subscribe_messages=True,

  File "/home/gitonga/frappe-bench/env/lib/python3.8/site-packages/redis/client.py", line 3617, in get_message
  File "/home/gitonga/frappe-bench/env/lib/python3.8/site-packages/redis/client.py", line 3617, in get_message
    response = self.parse_response(block=False, timeout=timeout)
  File "/home/gitonga/frappe-bench/env/lib/python3.8/site-packages/redis/client.py", line 3503, in parse_response
    response = self.parse_response(block=False, timeout=timeout)
  File "/home/gitonga/frappe-bench/env/lib/python3.8/site-packages/redis/client.py", line 3503, in parse_response
    if not block and not conn.can_read(timeout=timeout):
  File "/home/gitonga/frappe-bench/env/lib/python3.8/site-packages/redis/connection.py", line 734, in can_read
    if not block and not conn.can_read(timeout=timeout):
  File "/home/gitonga/frappe-bench/env/lib/python3.8/site-packages/redis/connection.py", line 734, in can_read
    return self._parser.can_read(timeout)
  File "/home/gitonga/frappe-bench/env/lib/python3.8/site-packages/redis/connection.py", line 321, in can_read
    return self._parser.can_read(timeout)
      File "/home/gitonga/frappe-bench/env/lib/python3.8/site-packages/redis/connection.py", line 321, in can_read
return self._buffer and self._buffer.can_read(timeout)
  File "/home/gitonga/frappe-bench/env/lib/python3.8/site-packages/redis/connection.py", line 230, in can_read
    self._read_from_socket(timeout=timeout,
      File "/home/gitonga/frappe-bench/env/lib/python3.8/site-packages/redis/connection.py", line 201, in _read_from_socket
return self._buffer and self._buffer.can_read(timeout)
  File "/home/gitonga/frappe-bench/env/lib/python3.8/site-packages/redis/connection.py", line 230, in can_read
    raise ConnectionError(SERVER_CLOSED_CONNECTION_ERROR)
redis.exceptions    .self._read_from_socket(timeout=timeout,ConnectionError
:   File "/home/gitonga/frappe-bench/env/lib/python3.8/site-packages/redis/connection.py", line 201, in _read_from_socket
Connection closed by server.
    raise ConnectionError(SERVER_CLOSED_CONNECTION_ERROR)
redis.exceptions.ConnectionError: Connection closed by server.
Exception in thread Exception in thread Thread-1:
Thread-1:
Traceback (most recent call last):
Traceback (most recent call last):
  File "/usr/lib/python3.8/threading.py", line 932, in _bootstrap_inner
  File "/usr/lib/python3.8/threading.py", line 932, in _bootstrap_inner
Exception in thread Thread-1:
Traceback (most recent call last):
  File "/usr/lib/python3.8/threading.py", line 932, in _bootstrap_inner
    self.run()
      File "/home/gitonga/frappe-bench/env/lib/python3.8/site-packages/redis/client.py", line 3718, in run
self.run()
  File "/home/gitonga/frappe-bench/env/lib/python3.8/site-packages/redis/client.py", line 3718, in run
    self.run()
  File "/home/gitonga/frappe-bench/env/lib/python3.8/site-packages/redis/client.py", line 3718, in run
    pubsub.get_message(ignore_subscribe_messages=True,
  File "/home/gitonga/frappe-bench/env/lib/python3.8/site-packages/redis/client.py", line 3617, in get_message
    pubsub.get_message(ignore_subscribe_messages=True,
  File "/home/gitonga/frappe-bench/env/lib/python3.8/site-packages/redis/client.py", line 3617, in get_message
    pubsub.get_message(ignore_subscribe_messages=True,
  File "/home/gitonga/frappe-bench/env/lib/python3.8/site-packages/redis/client.py", line 3617, in get_message
    response = self.parse_response(block=False, timeout=timeout)
  File "/home/gitonga/frappe-bench/env/lib/python3.8/site-packages/redis/client.py", line 3503, in parse_response
    response = self.parse_response(block=False, timeout=timeout)
  File "/home/gitonga/frappe-bench/env/lib/python3.8/site-packages/redis/client.py", line 3503, in parse_response
    response = self.parse_response(block=False, timeout=timeout)    
if not block and not conn.can_read(timeout=timeout):
  File "/home/gitonga/frappe-bench/env/lib/python3.8/site-packages/redis/client.py", line 3503, in parse_response
  File "/home/gitonga/frappe-bench/env/lib/python3.8/site-packages/redis/connection.py", line 734, in can_read
    return self._parser.can_read(timeout)
  File "/home/gitonga/frappe-bench/env/lib/python3.8/site-packages/redis/connection.py", line 321, in can_read
    return self._buffer and self._buffer.can_read(timeout)
  File "/home/gitonga/frappe-bench/env/lib/python3.8/site-packages/redis/connection.py", line 230, in can_read
    self._read_from_socket(timeout=timeout,
  File "/home/gitonga/frappe-bench/env/lib/python3.8/site-packages/redis/connection.py", line 201, in _read_from_socket
    raise ConnectionError(SERVER_CLOSED_CONNECTION_ERROR)
redis.exceptions.ConnectionError: Connection closed by server.
    if not block and not conn.can_read(timeout=timeout):
  File "/home/gitonga/frappe-bench/env/lib/python3.8/site-packages/redis/connection.py", line 734, in can_read
    if not block and not conn.can_read(timeout=timeout):
  File "/home/gitonga/frappe-bench/env/lib/python3.8/site-packages/redis/connection.py", line 734, in can_read
    return self._parser.can_read(timeout)
  File "/home/gitonga/frappe-bench/env/lib/python3.8/site-packages/redis/connection.py", line 321, in can_read
    return self._buffer and self._buffer.can_read(timeout)
  File "/home/gitonga/frappe-bench/env/lib/python3.8/site-packages/redis/connection.py", line 230, in can_read
    return self._parser.can_read(timeout)
  File "/home/gitonga/frappe-bench/env/lib/python3.8/site-packages/redis/connection.py", line 321, in can_read
    self._read_from_socket(timeout=timeout,
  File "/home/gitonga/frappe-bench/env/lib/python3.8/site-packages/redis/connection.py", line 201, in _read_from_socket
        return self._buffer and self._buffer.can_read(timeout)raise ConnectionError(SERVER_CLOSED_CONNECTION_ERROR)

  File "/home/gitonga/frappe-bench/env/lib/python3.8/site-packages/redis/connection.py", line 230, in can_read
redis.exceptions.ConnectionError: Connection closed by server.
    self._read_from_socket(timeout=timeout,
  File "/home/gitonga/frappe-bench/env/lib/python3.8/site-packages/redis/connection.py", line 201, in _read_from_socket
    raise ConnectionError(SERVER_CLOSED_CONNECTION_ERROR)
redis.exceptions.ConnectionError: Connection closed by server.
Exception in thread Thread-1:
Traceback (most recent call last):
  File "/usr/lib/python3.8/threading.py", line 932, in _bootstrap_inner
    self.run()Exception in thread 
Thread-1:
  File "/home/gitonga/frappe-bench/env/lib/python3.8/site-packages/redis/client.py", line 3718, in run
Traceback (most recent call last):
  File "/usr/lib/python3.8/threading.py", line 932, in _bootstrap_inner
    self.run()
  File "/home/gitonga/frappe-bench/env/lib/python3.8/site-packages/redis/client.py", line 3718, in run
    pubsub.get_message(ignore_subscribe_messages=True,
  File "/home/gitonga/frappe-bench/env/lib/python3.8/site-packages/redis/client.py", line 3617, in get_message
    pubsub.get_message(ignore_subscribe_messages=True,
  File "/home/gitonga/frappe-bench/env/lib/python3.8/site-packages/redis/client.py", line 3617, in get_message
    response = self.parse_response(block=False, timeout=timeout)
  File "/home/gitonga/frappe-bench/env/lib/python3.8/site-packages/redis/client.py", line 3503, in parse_response
    response = self.parse_response(block=False, timeout=timeout)
  File "/home/gitonga/frappe-bench/env/lib/python3.8/site-packages/redis/client.py", line 3503, in parse_response
Exception in thread Thread-1:
Traceback (most recent call last):
  File "/usr/lib/python3.8/threading.py", line 932, in _bootstrap_inner
    self.run()
  File "/home/gitonga/frappe-bench/env/lib/python3.8/site-packages/redis/client.py", line 3718, in run
    if not block and not conn.can_read(timeout=timeout):
  File "/home/gitonga/frappe-bench/env/lib/python3.8/site-packages/redis/connection.py", line 734, in can_read
    return self._parser.can_read(timeout)
  File "/home/gitonga/frappe-bench/env/lib/python3.8/site-packages/redis/connection.py", line 321, in can_read
    if not block and not conn.can_read(timeout=timeout):
  File "/home/gitonga/frappe-bench/env/lib/python3.8/site-packages/redis/connection.py", line 734, in can_read
    return self._buffer and self._buffer.can_read(timeout)
  File "/home/gitonga/frappe-bench/env/lib/python3.8/site-packages/redis/connection.py", line 230, in can_read
    self._read_from_socket(timeout=timeout,
  File "/home/gitonga/frappe-bench/env/lib/python3.8/site-packages/redis/connection.py", line 201, in _read_from_socket
    return self._parser.can_read(timeout)
  File "/home/gitonga/frappe-bench/env/lib/python3.8/site-packages/redis/connection.py", line 321, in can_read
    raise ConnectionError(SERVER_CLOSED_CONNECTION_ERROR)
redis.exceptions.ConnectionError: Connection closed by server.
    return self._buffer and self._buffer.can_read(timeout)
  File "/home/gitonga/frappe-bench/env/lib/python3.8/site-packages/redis/connection.py", line 230, in can_read
    pubsub.get_message(ignore_subscribe_messages=True,
  File "/home/gitonga/frappe-bench/env/lib/python3.8/site-packages/redis/client.py", line 3617, in get_message
    self._read_from_socket(timeout=timeout,
  File "/home/gitonga/frappe-bench/env/lib/python3.8/site-packages/redis/connection.py", line 201, in _read_from_socket
    raise ConnectionError(SERVER_CLOSED_CONNECTION_ERROR)
redis.exceptions.ConnectionError: Connection closed by server.
    response = self.parse_response(block=False, timeout=timeout)
  File "/home/gitonga/frappe-bench/env/lib/python3.8/site-packages/redis/client.py", line 3503, in parse_response
    if not block and not conn.can_read(timeout=timeout):
  File "/home/gitonga/frappe-bench/env/lib/python3.8/site-packages/redis/connection.py", line 734, in can_read
    return self._parser.can_read(timeout)
  File "/home/gitonga/frappe-bench/env/lib/python3.8/site-packages/redis/connection.py", line 321, in can_read
    return self._buffer and self._buffer.can_read(timeout)
  File "/home/gitonga/frappe-bench/env/lib/python3.8/site-packages/redis/connection.py", line 230, in can_read
    self._read_from_socket(timeout=timeout,
  File "/home/gitonga/frappe-bench/env/lib/python3.8/site-packages/redis/connection.py", line 201, in _read_from_socket
    raise ConnectionError(SERVER_CLOSED_CONNECTION_ERROR)
redis.exceptions.ConnectionError: Connection closed by server.
Exception in thread Thread-1:
Traceback (most recent call last):
  File "/usr/lib/python3.8/threading.py", line 932, in _bootstrap_inner
    self.run()
  File "/home/gitonga/frappe-bench/env/lib/python3.8/site-packages/redis/client.py", line 3718, in run
    pubsub.get_message(ignore_subscribe_messages=True,
  File "/home/gitonga/frappe-bench/env/lib/python3.8/site-packages/redis/client.py", line 3617, in get_message
    response = self.parse_response(block=False, timeout=timeout)
  File "/home/gitonga/frappe-bench/env/lib/python3.8/site-packages/redis/client.py", line 3503, in parse_response
    if not block and not conn.can_read(timeout=timeout):
  File "/home/gitonga/frappe-bench/env/lib/python3.8/site-packages/redis/connection.py", line 734, in can_read
    return self._parser.can_read(timeout)
  File "/home/gitonga/frappe-bench/env/lib/python3.8/site-packages/redis/connection.py", line 321, in can_read
    return self._buffer and self._buffer.can_read(timeout)
  File "/home/gitonga/frappe-bench/env/lib/python3.8/site-packages/redis/connection.py", line 230, in can_read
    self._read_from_socket(timeout=timeout,
  File "/home/gitonga/frappe-bench/env/lib/python3.8/site-packages/redis/connection.py", line 201, in _read_from_socket
    raise ConnectionError(SERVER_CLOSED_CONNECTION_ERROR)
redis.exceptions.ConnectionError: Connection closed by server.
Exception in thread Thread-1:
Traceback (most recent call last):
  File "/usr/lib/python3.8/threading.py", line 932, in _bootstrap_inner
Exception in thread Thread-1:
Traceback (most recent call last):
  File "/usr/lib/python3.8/threading.py", line 932, in _bootstrap_inner
    self.run()    self.run()

  File "/home/gitonga/frappe-bench/env/lib/python3.8/site-packages/redis/client.py", line 3718, in run
  File "/home/gitonga/frappe-bench/env/lib/python3.8/site-packages/redis/client.py", line 3718, in run
Exception in thread Thread-1:
Traceback (most recent call last):
  File "/usr/lib/python3.8/threading.py", line 932, in _bootstrap_inner
        pubsub.get_message(ignore_subscribe_messages=True,pubsub.get_message(ignore_subscribe_messages=True,

  File "/home/gitonga/frappe-bench/env/lib/python3.8/site-packages/redis/client.py", line 3617, in get_message
  File "/home/gitonga/frappe-bench/env/lib/python3.8/site-packages/redis/client.py", line 3617, in get_message
    self.run()
  File "/home/gitonga/frappe-bench/env/lib/python3.8/site-packages/redis/client.py", line 3718, in run
            response = self.parse_response(block=False, timeout=timeout)response = self.parse_response(block=False, timeout=timeout)pubsub.get_message(ignore_subscribe_messages=True,


  File "/home/gitonga/frappe-bench/env/lib/python3.8/site-packages/redis/client.py", line 3503, in parse_response
  File "/home/gitonga/frappe-bench/env/lib/python3.8/site-packages/redis/client.py", line 3503, in parse_response
  File "/home/gitonga/frappe-bench/env/lib/python3.8/site-packages/redis/client.py", line 3617, in get_message
        if not block and not conn.can_read(timeout=timeout):if not block and not conn.can_read(timeout=timeout):

      File "/home/gitonga/frappe-bench/env/lib/python3.8/site-packages/redis/connection.py", line 734, in can_read
  File "/home/gitonga/frappe-bench/env/lib/python3.8/site-packages/redis/connection.py", line 734, in can_read
response = self.parse_response(block=False, timeout=timeout)
  File "/home/gitonga/frappe-bench/env/lib/python3.8/site-packages/redis/client.py", line 3503, in parse_response
        return self._parser.can_read(timeout)return self._parser.can_read(timeout)

  File "/home/gitonga/frappe-bench/env/lib/python3.8/site-packages/redis/connection.py", line 321, in can_read
  File "/home/gitonga/frappe-bench/env/lib/python3.8/site-packages/redis/connection.py", line 321, in can_read
        return self._buffer and self._buffer.can_read(timeout)return self._buffer and self._buffer.can_read(timeout)

  File "/home/gitonga/frappe-bench/env/lib/python3.8/site-packages/redis/connection.py", line 230, in can_read
  File "/home/gitonga/frappe-bench/env/lib/python3.8/site-packages/redis/connection.py", line 230, in can_read
        self._read_from_socket(timeout=timeout,self._read_from_socket(timeout=timeout,

  File "/home/gitonga/frappe-bench/env/lib/python3.8/site-packages/redis/connection.py", line 201, in _read_from_socket
  File "/home/gitonga/frappe-bench/env/lib/python3.8/site-packages/redis/connection.py", line 201, in _read_from_socket
        raise ConnectionError(SERVER_CLOSED_CONNECTION_ERROR)raise ConnectionError(SERVER_CLOSED_CONNECTION_ERROR)

redis.exceptionsredis.exceptions..ConnectionErrorConnectionError: : Connection closed by server.Connection closed by server.

    if not block and not conn.can_read(timeout=timeout):
  File "/home/gitonga/frappe-bench/env/lib/python3.8/site-packages/redis/connection.py", line 734, in can_read
    return self._parser.can_read(timeout)
  File "/home/gitonga/frappe-bench/env/lib/python3.8/site-packages/redis/connection.py", line 321, in can_read
    return self._buffer and self._buffer.can_read(timeout)
  File "/home/gitonga/frappe-bench/env/lib/python3.8/site-packages/redis/connection.py", line 230, in can_read
    self._read_from_socket(timeout=timeout,
  File "/home/gitonga/frappe-bench/env/lib/python3.8/site-packages/redis/connection.py", line 201, in _read_from_socket
    raise ConnectionError(SERVER_CLOSED_CONNECTION_ERROR)
redis.exceptions.ConnectionError: Connection closed by server.
Exception in thread Thread-1:
Exception in thread Traceback (most recent call last):
Thread-1  File "/usr/lib/python3.8/threading.py", line 932, in _bootstrap_inner
:
Traceback (most recent call last):
  File "/usr/lib/python3.8/threading.py", line 932, in _bootstrap_inner
    self.run()
  File "/home/gitonga/frappe-bench/env/lib/python3.8/site-packages/redis/client.py", line 3718, in run
    self.run()
  File "/home/gitonga/frappe-bench/env/lib/python3.8/site-packages/redis/client.py", line 3718, in run
    pubsub.get_message(ignore_subscribe_messages=True,
  File "/home/gitonga/frappe-bench/env/lib/python3.8/site-packages/redis/client.py", line 3617, in get_message
    pubsub.get_message(ignore_subscribe_messages=True,
  File "/home/gitonga/frappe-bench/env/lib/python3.8/site-packages/redis/client.py", line 3617, in get_message
    response = self.parse_response(block=False, timeout=timeout)
  File "/home/gitonga/frappe-bench/env/lib/python3.8/site-packages/redis/client.py", line 3503, in parse_response
    response = self.parse_response(block=False, timeout=timeout)
  File "/home/gitonga/frappe-bench/env/lib/python3.8/site-packages/redis/client.py", line 3503, in parse_response
    if not block and not conn.can_read(timeout=timeout):
  File "/home/gitonga/frappe-bench/env/lib/python3.8/site-packages/redis/connection.py", line 734, in can_read
    if not block and not conn.can_read(timeout=timeout):
  File "/home/gitonga/frappe-bench/env/lib/python3.8/site-packages/redis/connection.py", line 734, in can_read
    return self._parser.can_read(timeout)
      File "/home/gitonga/frappe-bench/env/lib/python3.8/site-packages/redis/connection.py", line 321, in can_read
return self._parser.can_read(timeout)
  File "/home/gitonga/frappe-bench/env/lib/python3.8/site-packages/redis/connection.py", line 321, in can_read
    return self._buffer and self._buffer.can_read(timeout)
  File "/home/gitonga/frappe-bench/env/lib/python3.8/site-packages/redis/connection.py", line 230, in can_read
    return self._buffer and self._buffer.can_read(timeout)
  File "/home/gitonga/frappe-bench/env/lib/python3.8/site-packages/redis/connection.py", line 230, in can_read
    self._read_from_socket(timeout=timeout,
  File "/home/gitonga/frappe-bench/env/lib/python3.8/site-packages/redis/connection.py", line 201, in _read_from_socket
    raise ConnectionError(SERVER_CLOSED_CONNECTION_ERROR)
redis.exceptions.ConnectionError: Connection closed by server.    
self._read_from_socket(timeout=timeout,
  File "/home/gitonga/frappe-bench/env/lib/python3.8/site-packages/redis/connection.py", line 201, in _read_from_socket
    raise ConnectionError(SERVER_CLOSED_CONNECTION_ERROR)
redis.exceptions.ConnectionError: Connection closed by server.
Exception in thread Thread-1:
Traceback (most recent call last):
  File "/usr/lib/python3.8/threading.py", line 932, in _bootstrap_inner
    self.run()
  File "/home/gitonga/frappe-bench/env/lib/python3.8/site-packages/redis/client.py", line 3718, in run
    pubsub.get_message(ignore_subscribe_messages=True,
  File "/home/gitonga/frappe-bench/env/lib/python3.8/site-packages/redis/client.py", line 3617, in get_message
    response = self.parse_response(block=False, timeout=timeout)
  File "/home/gitonga/frappe-bench/env/lib/python3.8/site-packages/redis/client.py", line 3503, in parse_response
    if not block and not conn.can_read(timeout=timeout):
  File "/home/gitonga/frappe-bench/env/lib/python3.8/site-packages/redis/connection.py", line 734, in can_read
    return self._parser.can_read(timeout)
  File "/home/gitonga/frappe-bench/env/lib/python3.8/site-packages/redis/connection.py", line 321, in can_read
    return self._buffer and self._buffer.can_read(timeout)
  File "/home/gitonga/frappe-bench/env/lib/python3.8/site-packages/redis/connection.py", line 230, in can_read
    self._read_from_socket(timeout=timeout,
  File "/home/gitonga/frappe-bench/env/lib/python3.8/site-packages/redis/connection.py", line 201, in _read_from_socket
    raise ConnectionError(SERVER_CLOSED_CONNECTION_ERROR)
redis.exceptions.ConnectionError: Connection closed by server.
Exception in thread Thread-1:
Traceback (most recent call last):
  File "/usr/lib/python3.8/threading.py", line 932, in _bootstrap_inner
    self.run()
  File "/home/gitonga/frappe-bench/env/lib/python3.8/site-packages/redis/client.py", line 3718, in run
Exception in thread Thread-1:
Traceback (most recent call last):
  File "/usr/lib/python3.8/threading.py", line 932, in _bootstrap_inner
    self.run()
  File "/home/gitonga/frappe-bench/env/lib/python3.8/site-packages/redis/client.py", line 3718, in run
    pubsub.get_message(ignore_subscribe_messages=True,
  File "/home/gitonga/frappe-bench/env/lib/python3.8/site-packages/redis/client.py", line 3617, in get_message
    pubsub.get_message(ignore_subscribe_messages=True,
  File "/home/gitonga/frappe-bench/env/lib/python3.8/site-packages/redis/client.py", line 3617, in get_message
    response = self.parse_response(block=False, timeout=timeout)
  File "/home/gitonga/frappe-bench/env/lib/python3.8/site-packages/redis/client.py", line 3503, in parse_response
    response = self.parse_response(block=False, timeout=timeout)
  File "/home/gitonga/frappe-bench/env/lib/python3.8/site-packages/redis/client.py", line 3503, in parse_response
    if not block and not conn.can_read(timeout=timeout):
  File "/home/gitonga/frappe-bench/env/lib/python3.8/site-packages/redis/connection.py", line 734, in can_read
    return self._parser.can_read(timeout)
  File "/home/gitonga/frappe-bench/env/lib/python3.8/site-packages/redis/connection.py", line 321, in can_read
    return self._buffer and self._buffer.can_read(timeout)
  File "/home/gitonga/frappe-bench/env/lib/python3.8/site-packages/redis/connection.py", line 230, in can_read
    self._read_from_socket(timeout=timeout,
  File "/home/gitonga/frappe-bench/env/lib/python3.8/site-packages/redis/connection.py", line 201, in _read_from_socket
    raise ConnectionError(SERVER_CLOSED_CONNECTION_ERROR)
    redis.exceptionsif not block and not conn.can_read(timeout=timeout):.
ConnectionError:   File "/home/gitonga/frappe-bench/env/lib/python3.8/site-packages/redis/connection.py", line 734, in can_read
Connection closed by server.
    return self._parser.can_read(timeout)
  File "/home/gitonga/frappe-bench/env/lib/python3.8/site-packages/redis/connection.py", line 321, in can_read
Exception in thread Thread-1:
Traceback (most recent call last):
  File "/usr/lib/python3.8/threading.py", line 932, in _bootstrap_inner
    return self._buffer and self._buffer.can_read(timeout)
  File "/home/gitonga/frappe-bench/env/lib/python3.8/site-packages/redis/connection.py", line 230, in can_read
    self._read_from_socket(timeout=timeout,
  File "/home/gitonga/frappe-bench/env/lib/python3.8/site-packages/redis/connection.py", line 201, in _read_from_socket
    raise ConnectionError(SERVER_CLOSED_CONNECTION_ERROR)
redis.exceptions.ConnectionError: Connection closed by server.
    self.run()
  File "/home/gitonga/frappe-bench/env/lib/python3.8/site-packages/redis/client.py", line 3718, in run
    pubsub.get_message(ignore_subscribe_messages=True,
  File "/home/gitonga/frappe-bench/env/lib/python3.8/site-packages/redis/client.py", line 3617, in get_message
    response = self.parse_response(block=False, timeout=timeout)
  File "/home/gitonga/frappe-bench/env/lib/python3.8/site-packages/redis/client.py", line 3503, in parse_response
    if not block and not conn.can_read(timeout=timeout):
  File "/home/gitonga/frappe-bench/env/lib/python3.8/site-packages/redis/connection.py", line 734, in can_read
    return self._parser.can_read(timeout)
  File "/home/gitonga/frappe-bench/env/lib/python3.8/site-packages/redis/connection.py", line 321, in can_read
    return self._buffer and self._buffer.can_read(timeout)
  File "/home/gitonga/frappe-bench/env/lib/python3.8/site-packages/redis/connection.py", line 230, in can_read
    self._read_from_socket(timeout=timeout,
  File "/home/gitonga/frappe-bench/env/lib/python3.8/site-packages/redis/connection.py", line 201, in _read_from_socket
    raise ConnectionError(SERVER_CLOSED_CONNECTION_ERROR)
redis.exceptions.ConnectionError: Connection closed by server.
Exception in thread Thread-1:
Traceback (most recent call last):
  File "/usr/lib/python3.8/threading.py", line 932, in _bootstrap_inner
    self.run()
  File "/home/gitonga/frappe-bench/env/lib/python3.8/site-packages/redis/client.py", line 3718, in run
Exception in thread Thread-1:
Traceback (most recent call last):
  File "/usr/lib/python3.8/threading.py", line 932, in _bootstrap_inner
    self.run()
  File "/home/gitonga/frappe-bench/env/lib/python3.8/site-packages/redis/client.py", line 3718, in run
    pubsub.get_message(ignore_subscribe_messages=True,
  File "/home/gitonga/frappe-bench/env/lib/python3.8/site-packages/redis/client.py", line 3617, in get_message
    pubsub.get_message(ignore_subscribe_messages=True,
  File "/home/gitonga/frappe-bench/env/lib/python3.8/site-packages/redis/client.py", line 3617, in get_message
    response = self.parse_response(block=False, timeout=timeout)
  File "/home/gitonga/frappe-bench/env/lib/python3.8/site-packages/redis/client.py", line 3503, in parse_response
    response = self.parse_response(block=False, timeout=timeout)
  File "/home/gitonga/frappe-bench/env/lib/python3.8/site-packages/redis/client.py", line 3503, in parse_response
    if not block and not conn.can_read(timeout=timeout):
  File "/home/gitonga/frappe-bench/env/lib/python3.8/site-packages/redis/connection.py", line 734, in can_read
    if not block and not conn.can_read(timeout=timeout):
  File "/home/gitonga/frappe-bench/env/lib/python3.8/site-packages/redis/connection.py", line 734, in can_read
    return self._parser.can_read(timeout)
  File "/home/gitonga/frappe-bench/env/lib/python3.8/site-packages/redis/connection.py", line 321, in can_read
    return self._buffer and self._buffer.can_read(timeout)
  File "/home/gitonga/frappe-bench/env/lib/python3.8/site-packages/redis/connection.py", line 230, in can_read
    return self._parser.can_read(timeout)
  File "/home/gitonga/frappe-bench/env/lib/python3.8/site-packages/redis/connection.py", line 321, in can_read
    self._read_from_socket(timeout=timeout,
  File "/home/gitonga/frappe-bench/env/lib/python3.8/site-packages/redis/connection.py", line 201, in _read_from_socket
    return self._buffer and self._buffer.can_read(timeout)
  File "/home/gitonga/frappe-bench/env/lib/python3.8/site-packages/redis/connection.py", line 230, in can_read
    raise ConnectionError(SERVER_CLOSED_CONNECTION_ERROR)
redis.exceptions.ConnectionError: Connection closed by server.
    self._read_from_socket(timeout=timeout,
  File "/home/gitonga/frappe-bench/env/lib/python3.8/site-packages/redis/connection.py", line 201, in _read_from_socket
    raise ConnectionError(SERVER_CLOSED_CONNECTION_ERROR)
redis.exceptions.ConnectionError: Connection closed by server.
Exception in thread Thread-1:
Exception in thread Traceback (most recent call last):
Thread-1  File "/usr/lib/python3.8/threading.py", line 932, in _bootstrap_inner
:
Traceback (most recent call last):
  File "/usr/lib/python3.8/threading.py", line 932, in _bootstrap_inner
        self.run()self.run()

  File "/home/gitonga/frappe-bench/env/lib/python3.8/site-packages/redis/client.py", line 3718, in run
  File "/home/gitonga/frappe-bench/env/lib/python3.8/site-packages/redis/client.py", line 3718, in run
    pubsub.get_message(ignore_subscribe_messages=True,    
pubsub.get_message(ignore_subscribe_messages=True,
  File "/home/gitonga/frappe-bench/env/lib/python3.8/site-packages/redis/client.py", line 3617, in get_message
  File "/home/gitonga/frappe-bench/env/lib/python3.8/site-packages/redis/client.py", line 3617, in get_message
    response = self.parse_response(block=False, timeout=timeout)
  File "/home/gitonga/frappe-bench/env/lib/python3.8/site-packages/redis/client.py", line 3503, in parse_response
    response = self.parse_response(block=False, timeout=timeout)
  File "/home/gitonga/frappe-bench/env/lib/python3.8/site-packages/redis/client.py", line 3503, in parse_response
    if not block and not conn.can_read(timeout=timeout):
  File "/home/gitonga/frappe-bench/env/lib/python3.8/site-packages/redis/connection.py", line 734, in can_read
    if not block and not conn.can_read(timeout=timeout):
  File "/home/gitonga/frappe-bench/env/lib/python3.8/site-packages/redis/connection.py", line 734, in can_read
    return self._parser.can_read(timeout)
  File "/home/gitonga/frappe-bench/env/lib/python3.8/site-packages/redis/connection.py", line 321, in can_read
        return self._parser.can_read(timeout)return self._buffer and self._buffer.can_read(timeout)

  File "/home/gitonga/frappe-bench/env/lib/python3.8/site-packages/redis/connection.py", line 321, in can_read
  File "/home/gitonga/frappe-bench/env/lib/python3.8/site-packages/redis/connection.py", line 230, in can_read
    return self._buffer and self._buffer.can_read(timeout)
  File "/home/gitonga/frappe-bench/env/lib/python3.8/site-packages/redis/connection.py", line 230, in can_read
    self._read_from_socket(timeout=timeout,
  File "/home/gitonga/frappe-bench/env/lib/python3.8/site-packages/redis/connection.py", line 201, in _read_from_socket
Exception in thread Thread-1:
Traceback (most recent call last):
  File "/usr/lib/python3.8/threading.py", line 932, in _bootstrap_inner
    raise ConnectionError(SERVER_CLOSED_CONNECTION_ERROR)
redis.exceptions.ConnectionError: Connection closed by server.
    self.run()
  File "/home/gitonga/frappe-bench/env/lib/python3.8/site-packages/redis/client.py", line 3718, in run
    pubsub.get_message(ignore_subscribe_messages=True,
  File "/home/gitonga/frappe-bench/env/lib/python3.8/site-packages/redis/client.py", line 3617, in get_message
    response = self.parse_response(block=False, timeout=timeout)
  File "/home/gitonga/frappe-bench/env/lib/python3.8/site-packages/redis/client.py", line 3503, in parse_response
    if not block and not conn.can_read(timeout=timeout):
  File "/home/gitonga/frappe-bench/env/lib/python3.8/site-packages/redis/connection.py", line 734, in can_read
    return self._parser.can_read(timeout)
  File "/home/gitonga/frappe-bench/env/lib/python3.8/site-packages/redis/connection.py", line 321, in can_read
    return self._buffer and self._buffer.can_read(timeout)
  File "/home/gitonga/frappe-bench/env/lib/python3.8/site-packages/redis/connection.py", line 230, in can_read
    self._read_from_socket(timeout=timeout,
  File "/home/gitonga/frappe-bench/env/lib/python3.8/site-packages/redis/connection.py", line 201, in _read_from_socket
    raise ConnectionError(SERVER_CLOSED_CONNECTION_ERROR)
redis.exceptions.ConnectionError: Connection closed by server.
    self._read_from_socket(timeout=timeout,
  File "/home/gitonga/frappe-bench/env/lib/python3.8/site-packages/redis/connection.py", line 201, in _read_from_socket
    raise ConnectionError(SERVER_CLOSED_CONNECTION_ERROR)
redis.exceptions.ConnectionError: Connection closed by server.
Exception in thread Thread-1:
Exception in thread Traceback (most recent call last):
Thread-1  File "/usr/lib/python3.8/threading.py", line 932, in _bootstrap_inner
:
Traceback (most recent call last):
  File "/usr/lib/python3.8/threading.py", line 932, in _bootstrap_inner
        self.run()self.run()

  File "/home/gitonga/frappe-bench/env/lib/python3.8/site-packages/redis/client.py", line 3718, in run
  File "/home/gitonga/frappe-bench/env/lib/python3.8/site-packages/redis/client.py", line 3718, in run
        pubsub.get_message(ignore_subscribe_messages=True,pubsub.get_message(ignore_subscribe_messages=True,

  File "/home/gitonga/frappe-bench/env/lib/python3.8/site-packages/redis/client.py", line 3617, in get_message
  File "/home/gitonga/frappe-bench/env/lib/python3.8/site-packages/redis/client.py", line 3617, in get_message
    response = self.parse_response(block=False, timeout=timeout)
  File "/home/gitonga/frappe-bench/env/lib/python3.8/site-packages/redis/client.py", line 3503, in parse_response
    response = self.parse_response(block=False, timeout=timeout)
  File "/home/gitonga/frappe-bench/env/lib/python3.8/site-packages/redis/client.py", line 3503, in parse_response
    if not block and not conn.can_read(timeout=timeout):
  File "/home/gitonga/frappe-bench/env/lib/python3.8/site-packages/redis/connection.py", line 734, in can_read
    if not block and not conn.can_read(timeout=timeout):
  File "/home/gitonga/frappe-bench/env/lib/python3.8/site-packages/redis/connection.py", line 734, in can_read
    return self._parser.can_read(timeout)
  File "/home/gitonga/frappe-bench/env/lib/python3.8/site-packages/redis/connection.py", line 321, in can_read
        return self._parser.can_read(timeout)return self._buffer and self._buffer.can_read(timeout)

  File "/home/gitonga/frappe-bench/env/lib/python3.8/site-packages/redis/connection.py", line 321, in can_read
  File "/home/gitonga/frappe-bench/env/lib/python3.8/site-packages/redis/connection.py", line 230, in can_read
    self._read_from_socket(timeout=timeout,
  File "/home/gitonga/frappe-bench/env/lib/python3.8/site-packages/redis/connection.py", line 201, in _read_from_socket
    return self._buffer and self._buffer.can_read(timeout)
  File "/home/gitonga/frappe-bench/env/lib/python3.8/site-packages/redis/connection.py", line 230, in can_read
    raise ConnectionError(SERVER_CLOSED_CONNECTION_ERROR)
redis.exceptions.ConnectionError: Connection closed by server.    
self._read_from_socket(timeout=timeout,
  File "/home/gitonga/frappe-bench/env/lib/python3.8/site-packages/redis/connection.py", line 201, in _read_from_socket
    raise ConnectionError(SERVER_CLOSED_CONNECTION_ERROR)
redis.exceptions.ConnectionError: Connection closed by server.
Exception in thread Thread-1:
Traceback (most recent call last):
  File "/usr/lib/python3.8/threading.py", line 932, in _bootstrap_inner
19:08:41 Could not connect to Redis instance: Connection closed by server. Retrying in 1 seconds...
Exception in thread Thread-1:
Traceback (most recent call last):
  File "/usr/lib/python3.8/threading.py", line 932, in _bootstrap_inner
    self.run()
  File "/home/gitonga/frappe-bench/env/lib/python3.8/site-packages/redis/client.py", line 3718, in run
    self.run()
  File "/home/gitonga/frappe-bench/env/lib/python3.8/site-packages/redis/client.py", line 3718, in run
    pubsub.get_message(ignore_subscribe_messages=True,
  File "/home/gitonga/frappe-bench/env/lib/python3.8/site-packages/redis/client.py", line 3617, in get_message
    pubsub.get_message(ignore_subscribe_messages=True,
  File "/home/gitonga/frappe-bench/env/lib/python3.8/site-packages/redis/client.py", line 3617, in get_message
    response = self.parse_response(block=False, timeout=timeout)
  File "/home/gitonga/frappe-bench/env/lib/python3.8/site-packages/redis/client.py", line 3503, in parse_response
    response = self.parse_response(block=False, timeout=timeout)
  File "/home/gitonga/frappe-bench/env/lib/python3.8/site-packages/redis/client.py", line 3503, in parse_response
Exception in thread Thread-1:
Traceback (most recent call last):
  File "/usr/lib/python3.8/threading.py", line 932, in _bootstrap_inner
    if not block and not conn.can_read(timeout=timeout):
  File "/home/gitonga/frappe-bench/env/lib/python3.8/site-packages/redis/connection.py", line 734, in can_read
    self.run()
  File "/home/gitonga/frappe-bench/env/lib/python3.8/site-packages/redis/client.py", line 3718, in run
    return self._parser.can_read(timeout)
  File "/home/gitonga/frappe-bench/env/lib/python3.8/site-packages/redis/connection.py", line 321, in can_read
    return self._buffer and self._buffer.can_read(timeout)
  File "/home/gitonga/frappe-bench/env/lib/python3.8/site-packages/redis/connection.py", line 230, in can_read
    self._read_from_socket(timeout=timeout,
  File "/home/gitonga/frappe-bench/env/lib/python3.8/site-packages/redis/connection.py", line 201, in _read_from_socket
    raise ConnectionError(SERVER_CLOSED_CONNECTION_ERROR)
redis.exceptions.ConnectionError: Connection closed by server.
    pubsub.get_message(ignore_subscribe_messages=True,
  File "/home/gitonga/frappe-bench/env/lib/python3.8/site-packages/redis/client.py", line 3617, in get_message
19:08:41 Could not connect to Redis instance: Connection closed by server. Retrying in 1 seconds...
    response = self.parse_response(block=False, timeout=timeout)
  File "/home/gitonga/frappe-bench/env/lib/python3.8/site-packages/redis/client.py", line 3503, in parse_response
    if not block and not conn.can_read(timeout=timeout):
  File "/home/gitonga/frappe-bench/env/lib/python3.8/site-packages/redis/connection.py", line 734, in can_read
    return self._parser.can_read(timeout)
  File "/home/gitonga/frappe-bench/env/lib/python3.8/site-packages/redis/connection.py", line 321, in can_read
    return self._buffer and self._buffer.can_read(timeout)
  File "/home/gitonga/frappe-bench/env/lib/python3.8/site-packages/redis/connection.py", line 230, in can_read
    self._read_from_socket(timeout=timeout,
  File "/home/gitonga/frappe-bench/env/lib/python3.8/site-packages/redis/connection.py", line 201, in _read_from_socket
    raise ConnectionError(SERVER_CLOSED_CONNECTION_ERROR)
redis.exceptions.ConnectionError: Connection closed by server.
Traceback (most recent call last):
    if not block and not conn.can_read(timeout=timeout):  File "/home/gitonga/frappe-bench/env/lib/python3.8/site-packages/redis/connection.py", line 559, in connect

  File "/home/gitonga/frappe-bench/env/lib/python3.8/site-packages/redis/connection.py", line 734, in can_read
    sock = self._connect()
  File "/home/gitonga/frappe-bench/env/lib/python3.8/site-packages/redis/connection.py", line 615, in _connect
    return self._parser.can_read(timeout)
  File "/home/gitonga/frappe-bench/env/lib/python3.8/site-packages/redis/connection.py", line 321, in can_read
    return self._buffer and self._buffer.can_read(timeout)
  File "/home/gitonga/frappe-bench/env/lib/python3.8/site-packages/redis/connection.py", line 230, in can_read
    raise err
  File "/home/gitonga/frappe-bench/env/lib/python3.8/site-packages/redis/connection.py", line 603, in _connect
    self._read_from_socket(timeout=timeout,
  File "/home/gitonga/frappe-bench/env/lib/python3.8/site-packages/redis/connection.py", line 201, in _read_from_socket
    raise ConnectionError(SERVER_CLOSED_CONNECTION_ERROR)
redis.exceptions.    ConnectionErrorsock.connect(socket_address): 
Connection closed by server.
ConnectionRefusedError: [Errno 111] Connection refused

During handling of the above exception, another exception occurred:

Traceback (most recent call last):
  File "/usr/lib/python3.8/runpy.py", line 194, in _run_module_as_main
    return _run_code(code, main_globals, None,
  File "/usr/lib/python3.8/runpy.py", line 87, in _run_code
    exec(code, run_globals)
  File "/home/gitonga/frappe-bench/apps/frappe/frappe/utils/bench_helper.py", line 104, in <module>
    main()
  File "/home/gitonga/frappe-bench/apps/frappe/frappe/utils/bench_helper.py", line 18, in main
    click.Group(commands=commands)(prog_name='bench')
  File "/home/gitonga/frappe-bench/env/lib/python3.8/site-packages/click/core.py", line 829, in __call__
    return self.main(*args, **kwargs)
  File "/home/gitonga/frappe-bench/env/lib/python3.8/site-packages/click/core.py", line 782, in main
    rv = self.invoke(ctx)
  File "/home/gitonga/frappe-bench/env/lib/python3.8/site-packages/click/core.py", line 1259, in invoke
19:08:41 Could not connect to Redis instance: Connection closed by server. Retrying in 1 seconds...
    return _process_result(sub_ctx.command.invoke(sub_ctx))
  File "/home/gitonga/frappe-bench/env/lib/python3.8/site-packages/click/core.py", line 1259, in invoke
    return _process_result(sub_ctx.command.invoke(sub_ctx))
  File "/home/gitonga/frappe-bench/env/lib/python3.8/site-packages/click/core.py", line 1066, in invoke
    return ctx.invoke(self.callback, **ctx.params)
  File "/home/gitonga/frappe-bench/env/lib/python3.8/site-packages/click/core.py", line 610, in invoke
    return callback(*args, **kwargs)
  File "/home/gitonga/frappe-bench/apps/frappe/frappe/commands/scheduler.py", line 177, in start_worker
Traceback (most recent call last):
  File "/home/gitonga/frappe-bench/env/lib/python3.8/site-packages/redis/connection.py", line 559, in connect
    sock = self._connect()
  File "/home/gitonga/frappe-bench/env/lib/python3.8/site-packages/redis/connection.py", line 615, in _connect
    raise err
  File "/home/gitonga/frappe-bench/env/lib/python3.8/site-packages/redis/connection.py", line 603, in _connect
    sock.connect(socket_address)
ConnectionRefusedError: [Errno 111] Connection refused

During handling of the above exception, another exception occurred:

Traceback (most recent call last):
  File "/usr/lib/python3.8/runpy.py", line 194, in _run_module_as_main
    return _run_code(code, main_globals, None,
  File "/usr/lib/python3.8/runpy.py", line 87, in _run_code
    exec(code, run_globals)
  File "/home/gitonga/frappe-bench/apps/frappe/frappe/utils/bench_helper.py", line 104, in <module>
    main()
  File "/home/gitonga/frappe-bench/apps/frappe/frappe/utils/bench_helper.py", line 18, in main
    click.Group(commands=commands)(prog_name='bench')
  File "/home/gitonga/frappe-bench/env/lib/python3.8/site-packages/click/core.py", line 829, in __call__
    return self.main(*args, **kwargs)
  File "/home/gitonga/frappe-bench/env/lib/python3.8/site-packages/click/core.py", line 782, in main
    rv = self.invoke(ctx)
  File "/home/gitonga/frappe-bench/env/lib/python3.8/site-packages/click/core.py", line 1259, in invoke
    return _process_result(sub_ctx.command.invoke(sub_ctx))
  File "/home/gitonga/frappe-bench/env/lib/python3.8/site-packages/click/core.py", line 1259, in invoke
    return _process_result(sub_ctx.command.invoke(sub_ctx))
  File "/home/gitonga/frappe-bench/env/lib/python3.8/site-packages/click/core.py", line 1066, in invoke
    return ctx.invoke(self.callback, **ctx.params)
  File "/home/gitonga/frappe-bench/env/lib/python3.8/site-packages/click/core.py", line 610, in invoke
    return callback(*args, **kwargs)
  File "/home/gitonga/frappe-bench/apps/frappe/frappe/commands/scheduler.py", line 177, in start_worker
Traceback (most recent call last):
  File "/home/gitonga/frappe-bench/env/lib/python3.8/site-packages/redis/connection.py", line 559, in connect
    sock = self._connect()
  File "/home/gitonga/frappe-bench/env/lib/python3.8/site-packages/redis/connection.py", line 615, in _connect
    raise err
  File "/home/gitonga/frappe-bench/env/lib/python3.8/site-packages/redis/connection.py", line 603, in _connect
    sock.connect(socket_address)
ConnectionRefusedError: [Errno 111] Connection refused

During handling of the above exception, another exception occurred:

Traceback (most recent call last):
  File "/usr/lib/python3.8/runpy.py", line 194, in _run_module_as_main
    return _run_code(code, main_globals, None,
  File "/usr/lib/python3.8/runpy.py", line 87, in _run_code
    exec(code, run_globals)
  File "/home/gitonga/frappe-bench/apps/frappe/frappe/utils/bench_helper.py", line 104, in <module>
    main()
  File "/home/gitonga/frappe-bench/apps/frappe/frappe/utils/bench_helper.py", line 18, in main
    click.Group(commands=commands)(prog_name='bench')
  File "/home/gitonga/frappe-bench/env/lib/python3.8/site-packages/click/core.py", line 829, in __call__
    return self.main(*args, **kwargs)
  File "/home/gitonga/frappe-bench/env/lib/python3.8/site-packages/click/core.py", line 782, in main
    rv = self.invoke(ctx)
  File "/home/gitonga/frappe-bench/env/lib/python3.8/site-packages/click/core.py", line 1259, in invoke
    return _process_result(sub_ctx.command.invoke(sub_ctx))
  File "/home/gitonga/frappe-bench/env/lib/python3.8/site-packages/click/core.py", line 1259, in invoke
    return _process_result(sub_ctx.command.invoke(sub_ctx))
  File "/home/gitonga/frappe-bench/env/lib/python3.8/site-packages/click/core.py", line 1066, in invoke
    return ctx.invoke(self.callback, **ctx.params)
  File "/home/gitonga/frappe-bench/env/lib/python3.8/site-packages/click/core.py", line 610, in invoke
    return callback(*args, **kwargs)
  File "/home/gitonga/frappe-bench/apps/frappe/frappe/commands/scheduler.py", line 177, in start_worker
    start_worker(queue, quiet = quiet)
      File "/home/gitonga/frappe-bench/apps/frappe/frappe/utils/background_jobs.py", line 148, in start_worker
start_worker(queue, quiet = quiet)
  File "/home/gitonga/frappe-bench/apps/frappe/frappe/utils/background_jobs.py", line 148, in start_worker
    start_worker(queue, quiet = quiet)
  File "/home/gitonga/frappe-bench/apps/frappe/frappe/utils/background_jobs.py", line 148, in start_worker
    Worker(queues, name=get_worker_name(queue)).work(logging_level = logging_level)    
Worker(queues, name=get_worker_name(queue)).work(logging_level = logging_level)
  File "/home/gitonga/frappe-bench/env/lib/python3.8/site-packages/rq/worker.py", line 626, in work
  File "/home/gitonga/frappe-bench/env/lib/python3.8/site-packages/rq/worker.py", line 626, in work
    Worker(queues, name=get_worker_name(queue)).work(logging_level = logging_level)
  File "/home/gitonga/frappe-bench/env/lib/python3.8/site-packages/rq/worker.py", line 626, in work
        self.register_death()self.register_death()

  File "/home/gitonga/frappe-bench/env/lib/python3.8/site-packages/rq/worker.py", line 326, in register_death
  File "/home/gitonga/frappe-bench/env/lib/python3.8/site-packages/rq/worker.py", line 326, in register_death
    p.execute()
  File "/home/gitonga/frappe-bench/env/lib/python3.8/site-packages/redis/client.py", line 4012, in execute
    p.execute()
  File "/home/gitonga/frappe-bench/env/lib/python3.8/site-packages/redis/client.py", line 4012, in execute
    self.register_death()
  File "/home/gitonga/frappe-bench/env/lib/python3.8/site-packages/rq/worker.py", line 326, in register_death
    p.execute()
  File "/home/gitonga/frappe-bench/env/lib/python3.8/site-packages/redis/client.py", line 4012, in execute
        conn = self.connection_pool.get_connection('MULTI',conn = self.connection_pool.get_connection('MULTI',

  File "/home/gitonga/frappe-bench/env/lib/python3.8/site-packages/redis/connection.py", line 1192, in get_connection
  File "/home/gitonga/frappe-bench/env/lib/python3.8/site-packages/redis/connection.py", line 1192, in get_connection
    conn = self.connection_pool.get_connection('MULTI',
  File "/home/gitonga/frappe-bench/env/lib/python3.8/site-packages/redis/connection.py", line 1192, in get_connection
        connection.connect()connection.connect()

  File "/home/gitonga/frappe-bench/env/lib/python3.8/site-packages/redis/connection.py", line 563, in connect
  File "/home/gitonga/frappe-bench/env/lib/python3.8/site-packages/redis/connection.py", line 563, in connect
    connection.connect()
  File "/home/gitonga/frappe-bench/env/lib/python3.8/site-packages/redis/connection.py", line 563, in connect
        raise ConnectionError(self._error_message(e))raise ConnectionError(self._error_message(e))

redis.exceptionsredis.exceptions..ConnectionErrorConnectionError: : Error 111 connecting to localhost:11000. Connection refused.Error 111 connecting to localhost:11000. Connection refused.

    raise ConnectionError(self._error_message(e))
redis.exceptions.ConnectionError: Error 111 connecting to localhost:11000. Connection refused.
Exception in thread Exception in thread Thread-1:
Thread-1:
Traceback (most recent call last):
Traceback (most recent call last):
  File "/usr/lib/python3.8/threading.py", line 932, in _bootstrap_inner
  File "/usr/lib/python3.8/threading.py", line 932, in _bootstrap_inner
Exception in thread Thread-1:
Traceback (most recent call last):
  File "/usr/lib/python3.8/threading.py", line 932, in _bootstrap_inner
    self.run()
  File "/home/gitonga/frappe-bench/env/lib/python3.8/site-packages/redis/client.py", line 3718, in run
    self.run()    
self.run()  File "/home/gitonga/frappe-bench/env/lib/python3.8/site-packages/redis/client.py", line 3718, in run

  File "/home/gitonga/frappe-bench/env/lib/python3.8/site-packages/redis/client.py", line 3718, in run
    pubsub.get_message(ignore_subscribe_messages=True,
  File "/home/gitonga/frappe-bench/env/lib/python3.8/site-packages/redis/client.py", line 3617, in get_message
    pubsub.get_message(ignore_subscribe_messages=True,
      File "/home/gitonga/frappe-bench/env/lib/python3.8/site-packages/redis/client.py", line 3617, in get_message
pubsub.get_message(ignore_subscribe_messages=True,
  File "/home/gitonga/frappe-bench/env/lib/python3.8/site-packages/redis/client.py", line 3617, in get_message
    response = self.parse_response(block=False, timeout=timeout)
  File "/home/gitonga/frappe-bench/env/lib/python3.8/site-packages/redis/client.py", line 3503, in parse_response
    response = self.parse_response(block=False, timeout=timeout)
      File "/home/gitonga/frappe-bench/env/lib/python3.8/site-packages/redis/client.py", line 3503, in parse_response
response = self.parse_response(block=False, timeout=timeout)
  File "/home/gitonga/frappe-bench/env/lib/python3.8/site-packages/redis/client.py", line 3503, in parse_response
    if not block and not conn.can_read(timeout=timeout):
  File "/home/gitonga/frappe-bench/env/lib/python3.8/site-packages/redis/connection.py", line 734, in can_read
    return self._parser.can_read(timeout)
  File "/home/gitonga/frappe-bench/env/lib/python3.8/site-packages/redis/connection.py", line 321, in can_read
        return self._buffer and self._buffer.can_read(timeout)if not block and not conn.can_read(timeout=timeout):

      File "/home/gitonga/frappe-bench/env/lib/python3.8/site-packages/redis/connection.py", line 230, in can_read
  File "/home/gitonga/frappe-bench/env/lib/python3.8/site-packages/redis/connection.py", line 734, in can_read
if not block and not conn.can_read(timeout=timeout):
  File "/home/gitonga/frappe-bench/env/lib/python3.8/site-packages/redis/connection.py", line 734, in can_read
    self._read_from_socket(timeout=timeout,
  File "/home/gitonga/frappe-bench/env/lib/python3.8/site-packages/redis/connection.py", line 201, in _read_from_socket
    raise ConnectionError(SERVER_CLOSED_CONNECTION_ERROR)
redis.exceptions.ConnectionError: Connection closed by server.
    return self._parser.can_read(timeout)    
return self._parser.can_read(timeout)  File "/home/gitonga/frappe-bench/env/lib/python3.8/site-packages/redis/connection.py", line 321, in can_read
    return self._buffer and self._buffer.can_read(timeout)
  File "/home/gitonga/frappe-bench/env/lib/python3.8/site-packages/redis/connection.py", line 230, in can_read
    self._read_from_socket(timeout=timeout,
  File "/home/gitonga/frappe-bench/env/lib/python3.8/site-packages/redis/connection.py", line 201, in _read_from_socket
    raise ConnectionError(SERVER_CLOSED_CONNECTION_ERROR)
redis.exceptions.ConnectionError: Connection closed by server.

  File "/home/gitonga/frappe-bench/env/lib/python3.8/site-packages/redis/connection.py", line 321, in can_read
    return self._buffer and self._buffer.can_read(timeout)
  File "/home/gitonga/frappe-bench/env/lib/python3.8/site-packages/redis/connection.py", line 230, in can_read
    self._read_from_socket(timeout=timeout,
  File "/home/gitonga/frappe-bench/env/lib/python3.8/site-packages/redis/connection.py", line 201, in _read_from_socket
    raise ConnectionError(SERVER_CLOSED_CONNECTION_ERROR)
redis.exceptions.ConnectionError: Connection closed by server.
Traceback (most recent call last):
  File "/home/gitonga/frappe-bench/env/lib/python3.8/site-packages/redis/connection.py", line 559, in connect
    sock = self._connect()
  File "/home/gitonga/frappe-bench/env/lib/python3.8/site-packages/redis/connection.py", line 615, in _connect
Exception in thread Thread-1Exception in thread :
Thread-1Traceback (most recent call last):
:
  File "/usr/lib/python3.8/threading.py", line 932, in _bootstrap_inner
Traceback (most recent call last):
  File "/usr/lib/python3.8/threading.py", line 932, in _bootstrap_inner
    raise err
  File "/home/gitonga/frappe-bench/env/lib/python3.8/site-packages/redis/connection.py", line 603, in _connect
    self.run()
          File "/home/gitonga/frappe-bench/env/lib/python3.8/site-packages/redis/client.py", line 3718, in run
self.run()sock.connect(socket_address)

  File "/home/gitonga/frappe-bench/env/lib/python3.8/site-packages/redis/client.py", line 3718, in run
ConnectionResetError: [Errno 104] Connection reset by peer

During handling of the above exception, another exception occurred:

Traceback (most recent call last):
  File "/usr/lib/python3.8/runpy.py", line 194, in _run_module_as_main
    return _run_code(code, main_globals, None,
  File "/usr/lib/python3.8/runpy.py", line 87, in _run_code
    exec(code, run_globals)
  File "/home/gitonga/frappe-bench/apps/frappe/frappe/utils/bench_helper.py", line 104, in <module>
    main()
  File "/home/gitonga/frappe-bench/apps/frappe/frappe/utils/bench_helper.py", line 18, in main
    click.Group(commands=commands)(prog_name='bench')
  File "/home/gitonga/frappe-bench/env/lib/python3.8/site-packages/click/core.py", line 829, in __call__
    return self.main(*args, **kwargs)
  File "/home/gitonga/frappe-bench/env/lib/python3.8/site-packages/click/core.py", line 782, in main
    pubsub.get_message(ignore_subscribe_messages=True,
  File "/home/gitonga/frappe-bench/env/lib/python3.8/site-packages/redis/client.py", line 3617, in get_message
    rv = self.invoke(ctx)
  File "/home/gitonga/frappe-bench/env/lib/python3.8/site-packages/click/core.py", line 1259, in invoke
    pubsub.get_message(ignore_subscribe_messages=True,
  File "/home/gitonga/frappe-bench/env/lib/python3.8/site-packages/redis/client.py", line 3617, in get_message
    return _process_result(sub_ctx.command.invoke(sub_ctx))
  File "/home/gitonga/frappe-bench/env/lib/python3.8/site-packages/click/core.py", line 1259, in invoke
    return _process_result(sub_ctx.command.invoke(sub_ctx))
  File "/home/gitonga/frappe-bench/env/lib/python3.8/site-packages/click/core.py", line 1066, in invoke
    response = self.parse_response(block=False, timeout=timeout)
  File "/home/gitonga/frappe-bench/env/lib/python3.8/site-packages/redis/client.py", line 3503, in parse_response
    response = self.parse_response(block=False, timeout=timeout)
  File "/home/gitonga/frappe-bench/env/lib/python3.8/site-packages/redis/client.py", line 3503, in parse_response
    return ctx.invoke(self.callback, **ctx.params)
  File "/home/gitonga/frappe-bench/env/lib/python3.8/site-packages/click/core.py", line 610, in invoke
    return callback(*args, **kwargs)
  File "/home/gitonga/frappe-bench/apps/frappe/frappe/commands/scheduler.py", line 177, in start_worker
    start_worker(queue, quiet = quiet)
  File "/home/gitonga/frappe-bench/apps/frappe/frappe/utils/background_jobs.py", line 148, in start_worker
    Worker(queues, name=get_worker_name(queue)).work(logging_level = logging_level)
  File "/home/gitonga/frappe-bench/env/lib/python3.8/site-packages/rq/worker.py", line 627, in work
    if not block and not conn.can_read(timeout=timeout):    
self.unsubscribe()
  File "/home/gitonga/frappe-bench/env/lib/python3.8/site-packages/redis/connection.py", line 734, in can_read
  File "/home/gitonga/frappe-bench/env/lib/python3.8/site-packages/rq/worker.py", line 532, in unsubscribe
    self.pubsub.unsubscribe()
  File "/home/gitonga/frappe-bench/env/lib/python3.8/site-packages/redis/client.py", line 3600, in unsubscribe
    return self._parser.can_read(timeout)
  File "/home/gitonga/frappe-bench/env/lib/python3.8/site-packages/redis/connection.py", line 321, in can_read
    return self._buffer and self._buffer.can_read(timeout)
  File "/home/gitonga/frappe-bench/env/lib/python3.8/site-packages/redis/connection.py", line 230, in can_read
        self._read_from_socket(timeout=timeout,if not block and not conn.can_read(timeout=timeout):

  File "/home/gitonga/frappe-bench/env/lib/python3.8/site-packages/redis/connection.py", line 201, in _read_from_socket
  File "/home/gitonga/frappe-bench/env/lib/python3.8/site-packages/redis/connection.py", line 734, in can_read
    raise ConnectionError(SERVER_CLOSED_CONNECTION_ERROR)
redis.exceptions.ConnectionError: Connection closed by server.
    return self._parser.can_read(timeout)
  File "/home/gitonga/frappe-bench/env/lib/python3.8/site-packages/redis/connection.py", line 321, in can_read
    return self._buffer and self._buffer.can_read(timeout)
  File "/home/gitonga/frappe-bench/env/lib/python3.8/site-packages/redis/connection.py", line 230, in can_read
    self._read_from_socket(timeout=timeout,
  File "/home/gitonga/frappe-bench/env/lib/python3.8/site-packages/redis/connection.py", line 201, in _read_from_socket
    raise ConnectionError(SERVER_CLOSED_CONNECTION_ERROR)
redis.exceptions.ConnectionError: Connection closed by server.
    return self.execute_command('UNSUBSCRIBE', *args)
  File "/home/gitonga/frappe-bench/env/lib/python3.8/site-packages/redis/client.py", line 3466, in execute_command
    self.connection = self.connection_pool.get_connection(
  File "/home/gitonga/frappe-bench/env/lib/python3.8/site-packages/redis/connection.py", line 1192, in get_connection
    connection.connect()
  File "/home/gitonga/frappe-bench/env/lib/python3.8/site-packages/redis/connection.py", line 563, in connect
    raise ConnectionError(self._error_message(e))
redis.exceptions.ConnectionError: Error 104 connecting to localhost:11000. Connection reset by peer.
Exception in thread Thread-1:
Traceback (most recent call last):
  File "/usr/lib/python3.8/threading.py", line 932, in _bootstrap_inner
    self.run()
  File "/home/gitonga/frappe-bench/env/lib/python3.8/site-packages/redis/client.py", line 3718, in run
    pubsub.get_message(ignore_subscribe_messages=True,
  File "/home/gitonga/frappe-bench/env/lib/python3.8/site-packages/redis/client.py", line 3617, in get_message
    response = self.parse_response(block=False, timeout=timeout)
  File "/home/gitonga/frappe-bench/env/lib/python3.8/site-packages/redis/client.py", line 3503, in parse_response
    if not block and not conn.can_read(timeout=timeout):
  File "/home/gitonga/frappe-bench/env/lib/python3.8/site-packages/redis/connection.py", line 734, in can_read
    return self._parser.can_read(timeout)
  File "/home/gitonga/frappe-bench/env/lib/python3.8/site-packages/redis/connection.py", line 321, in can_read
    return self._buffer and self._buffer.can_read(timeout)
  File "/home/gitonga/frappe-bench/env/lib/python3.8/site-packages/redis/connection.py", line 230, in can_read
    self._read_from_socket(timeout=timeout,
  File "/home/gitonga/frappe-bench/env/lib/python3.8/site-packages/redis/connection.py", line 201, in _read_from_socket
    raise ConnectionError(SERVER_CLOSED_CONNECTION_ERROR)
redis.exceptions.ConnectionError: Connection closed by server.
Exception in thread Thread-1:
Traceback (most recent call last):
  File "/usr/lib/python3.8/threading.py", line 932, in _bootstrap_inner
    self.run()
  File "/home/gitonga/frappe-bench/env/lib/python3.8/site-packages/redis/client.py", line 3718, in run
    pubsub.get_message(ignore_subscribe_messages=True,
  File "/home/gitonga/frappe-bench/env/lib/python3.8/site-packages/redis/client.py", line 3617, in get_message
    response = self.parse_response(block=False, timeout=timeout)
  File "/home/gitonga/frappe-bench/env/lib/python3.8/site-packages/redis/client.py", line 3503, in parse_response
Exception in thread Thread-1:
Traceback (most recent call last):
  File "/usr/lib/python3.8/threading.py", line 932, in _bootstrap_inner
    if not block and not conn.can_read(timeout=timeout):
  File "/home/gitonga/frappe-bench/env/lib/python3.8/site-packages/redis/connection.py", line 734, in can_read
    self.run()
  File "/home/gitonga/frappe-bench/env/lib/python3.8/site-packages/redis/client.py", line 3718, in run
    return self._parser.can_read(timeout)
  File "/home/gitonga/frappe-bench/env/lib/python3.8/site-packages/redis/connection.py", line 321, in can_read
    return self._buffer and self._buffer.can_read(timeout)
  File "/home/gitonga/frappe-bench/env/lib/python3.8/site-packages/redis/connection.py", line 230, in can_read
    self._read_from_socket(timeout=timeout,
  File "/home/gitonga/frappe-bench/env/lib/python3.8/site-packages/redis/connection.py", line 201, in _read_from_socket
    raise ConnectionError(SERVER_CLOSED_CONNECTION_ERROR)
redis.exceptions.ConnectionError: Connection closed by server.
    pubsub.get_message(ignore_subscribe_messages=True,
  File "/home/gitonga/frappe-bench/env/lib/python3.8/site-packages/redis/client.py", line 3617, in get_message
    response = self.parse_response(block=False, timeout=timeout)
  File "/home/gitonga/frappe-bench/env/lib/python3.8/site-packages/redis/client.py", line 3503, in parse_response
    if not block and not conn.can_read(timeout=timeout):
  File "/home/gitonga/frappe-bench/env/lib/python3.8/site-packages/redis/connection.py", line 734, in can_read
    return self._parser.can_read(timeout)
  File "/home/gitonga/frappe-bench/env/lib/python3.8/site-packages/redis/connection.py", line 321, in can_read
    return self._buffer and self._buffer.can_read(timeout)
  File "/home/gitonga/frappe-bench/env/lib/python3.8/site-packages/redis/connection.py", line 230, in can_read
    self._read_from_socket(timeout=timeout,
  File "/home/gitonga/frappe-bench/env/lib/python3.8/site-packages/redis/connection.py", line 201, in _read_from_socket
    raise ConnectionError(SERVER_CLOSED_CONNECTION_ERROR)
redis.exceptions.ConnectionError: Connection closed by server.
Exception in thread Thread-1:
Traceback (most recent call last):
  File "/usr/lib/python3.8/threading.py", line 932, in _bootstrap_inner
    self.run()
  File "/home/gitonga/frappe-bench/env/lib/python3.8/site-packages/redis/client.py", line 3718, in run
    pubsub.get_message(ignore_subscribe_messages=True,
  File "/home/gitonga/frappe-bench/env/lib/python3.8/site-packages/redis/client.py", line 3617, in get_message
Exception in thread Thread-1:
Traceback (most recent call last):
  File "/usr/lib/python3.8/threading.py", line 932, in _bootstrap_inner
        self.run()response = self.parse_response(block=False, timeout=timeout)
  File "/home/gitonga/frappe-bench/env/lib/python3.8/site-packages/redis/client.py", line 3503, in parse_response

  File "/home/gitonga/frappe-bench/env/lib/python3.8/site-packages/redis/client.py", line 3718, in run
    if not block and not conn.can_read(timeout=timeout):
  File "/home/gitonga/frappe-bench/env/lib/python3.8/site-packages/redis/connection.py", line 734, in can_read
    pubsub.get_message(ignore_subscribe_messages=True,
  File "/home/gitonga/frappe-bench/env/lib/python3.8/site-packages/redis/client.py", line 3617, in get_message
    return self._parser.can_read(timeout)
  File "/home/gitonga/frappe-bench/env/lib/python3.8/site-packages/redis/connection.py", line 321, in can_read
    return self._buffer and self._buffer.can_read(timeout)
  File "/home/gitonga/frappe-bench/env/lib/python3.8/site-packages/redis/connection.py", line 230, in can_read
    self._read_from_socket(timeout=timeout,
  File "/home/gitonga/frappe-bench/env/lib/python3.8/site-packages/redis/connection.py", line 201, in _read_from_socket
    raise ConnectionError(SERVER_CLOSED_CONNECTION_ERROR)
redis.exceptions.ConnectionError: Connection closed by server.
    response = self.parse_response(block=False, timeout=timeout)
  File "/home/gitonga/frappe-bench/env/lib/python3.8/site-packages/redis/client.py", line 3503, in parse_response
    if not block and not conn.can_read(timeout=timeout):
  File "/home/gitonga/frappe-bench/env/lib/python3.8/site-packages/redis/connection.py", line 734, in can_read
    return self._parser.can_read(timeout)
  File "/home/gitonga/frappe-bench/env/lib/python3.8/site-packages/redis/connection.py", line 321, in can_read
    return self._buffer and self._buffer.can_read(timeout)
  File "/home/gitonga/frappe-bench/env/lib/python3.8/site-packages/redis/connection.py", line 230, in can_read
    self._read_from_socket(timeout=timeout,
  File "/home/gitonga/frappe-bench/env/lib/python3.8/site-packages/redis/connection.py", line 201, in _read_from_socket
    raise ConnectionError(SERVER_CLOSED_CONNECTION_ERROR)
redis.exceptions.ConnectionError: Connection closed by server.
Exception in thread Thread-1:
Exception in thread Traceback (most recent call last):
Thread-1  File "/usr/lib/python3.8/threading.py", line 932, in _bootstrap_inner
:
Traceback (most recent call last):
  File "/usr/lib/python3.8/threading.py", line 932, in _bootstrap_inner
    self.run()
  File "/home/gitonga/frappe-bench/env/lib/python3.8/site-packages/redis/client.py", line 3718, in run
    self.run()
  File "/home/gitonga/frappe-bench/env/lib/python3.8/site-packages/redis/client.py", line 3718, in run
    pubsub.get_message(ignore_subscribe_messages=True,
  File "/home/gitonga/frappe-bench/env/lib/python3.8/site-packages/redis/client.py", line 3617, in get_message
    pubsub.get_message(ignore_subscribe_messages=True,
  File "/home/gitonga/frappe-bench/env/lib/python3.8/site-packages/redis/client.py", line 3617, in get_message
    response = self.parse_response(block=False, timeout=timeout)
  File "/home/gitonga/frappe-bench/env/lib/python3.8/site-packages/redis/client.py", line 3503, in parse_response
Exception in thread Thread-1:
Traceback (most recent call last):
  File "/usr/lib/python3.8/threading.py", line 932, in _bootstrap_inner
    self.run()
  File "/home/gitonga/frappe-bench/env/lib/python3.8/site-packages/redis/client.py", line 3718, in run
        response = self.parse_response(block=False, timeout=timeout)if not block and not conn.can_read(timeout=timeout):

  File "/home/gitonga/frappe-bench/env/lib/python3.8/site-packages/redis/client.py", line 3503, in parse_response
  File "/home/gitonga/frappe-bench/env/lib/python3.8/site-packages/redis/connection.py", line 734, in can_read
    return self._parser.can_read(timeout)
  File "/home/gitonga/frappe-bench/env/lib/python3.8/site-packages/redis/connection.py", line 321, in can_read
    return self._buffer and self._buffer.can_read(timeout)
  File "/home/gitonga/frappe-bench/env/lib/python3.8/site-packages/redis/connection.py", line 230, in can_read
    self._read_from_socket(timeout=timeout,
  File "/home/gitonga/frappe-bench/env/lib/python3.8/site-packages/redis/connection.py", line 201, in _read_from_socket
    raise ConnectionError(SERVER_CLOSED_CONNECTION_ERROR)
redis.exceptions.ConnectionError: Connection closed by server.
    if not block and not conn.can_read(timeout=timeout):
  File "/home/gitonga/frappe-bench/env/lib/python3.8/site-packages/redis/connection.py", line 734, in can_read
    pubsub.get_message(ignore_subscribe_messages=True,
  File "/home/gitonga/frappe-bench/env/lib/python3.8/site-packages/redis/client.py", line 3617, in get_message
    return self._parser.can_read(timeout)
  File "/home/gitonga/frappe-bench/env/lib/python3.8/site-packages/redis/connection.py", line 321, in can_read
    return self._buffer and self._buffer.can_read(timeout)
  File "/home/gitonga/frappe-bench/env/lib/python3.8/site-packages/redis/connection.py", line 230, in can_read
    self._read_from_socket(timeout=timeout,
  File "/home/gitonga/frappe-bench/env/lib/python3.8/site-packages/redis/connection.py", line 201, in _read_from_socket
    raise ConnectionError(SERVER_CLOSED_CONNECTION_ERROR)
redis.exceptions.ConnectionError: Connection closed by server.
    response = self.parse_response(block=False, timeout=timeout)
  File "/home/gitonga/frappe-bench/env/lib/python3.8/site-packages/redis/client.py", line 3503, in parse_response
    if not block and not conn.can_read(timeout=timeout):
  File "/home/gitonga/frappe-bench/env/lib/python3.8/site-packages/redis/connection.py", line 734, in can_read
    return self._parser.can_read(timeout)
  File "/home/gitonga/frappe-bench/env/lib/python3.8/site-packages/redis/connection.py", line 321, in can_read
    return self._buffer and self._buffer.can_read(timeout)
  File "/home/gitonga/frappe-bench/env/lib/python3.8/site-packages/redis/connection.py", line 230, in can_read
    self._read_from_socket(timeout=timeout,
  File "/home/gitonga/frappe-bench/env/lib/python3.8/site-packages/redis/connection.py", line 201, in _read_from_socket
    raise ConnectionError(SERVER_CLOSED_CONNECTION_ERROR)
redis.exceptions.ConnectionError: Connection closed by server.
Exception in thread Exception in thread Thread-1Thread-1:
:
Traceback (most recent call last):
Traceback (most recent call last):
  File "/usr/lib/python3.8/threading.py", line 932, in _bootstrap_inner
  File "/usr/lib/python3.8/threading.py", line 932, in _bootstrap_inner
        self.run()self.run()

  File "/home/gitonga/frappe-bench/env/lib/python3.8/site-packages/redis/client.py", line 3718, in run
  File "/home/gitonga/frappe-bench/env/lib/python3.8/site-packages/redis/client.py", line 3718, in run
Exception in thread Thread-1:
Traceback (most recent call last):
  File "/usr/lib/python3.8/threading.py", line 932, in _bootstrap_inner
        pubsub.get_message(ignore_subscribe_messages=True,pubsub.get_message(ignore_subscribe_messages=True,

  File "/home/gitonga/frappe-bench/env/lib/python3.8/site-packages/redis/client.py", line 3617, in get_message
  File "/home/gitonga/frappe-bench/env/lib/python3.8/site-packages/redis/client.py", line 3617, in get_message
    self.run()
  File "/home/gitonga/frappe-bench/env/lib/python3.8/site-packages/redis/client.py", line 3718, in run
        response = self.parse_response(block=False, timeout=timeout)response = self.parse_response(block=False, timeout=timeout)

  File "/home/gitonga/frappe-bench/env/lib/python3.8/site-packages/redis/client.py", line 3503, in parse_response
  File "/home/gitonga/frappe-bench/env/lib/python3.8/site-packages/redis/client.py", line 3503, in parse_response
    pubsub.get_message(ignore_subscribe_messages=True,
  File "/home/gitonga/frappe-bench/env/lib/python3.8/site-packages/redis/client.py", line 3617, in get_message
    response = self.parse_response(block=False, timeout=timeout)
  File "/home/gitonga/frappe-bench/env/lib/python3.8/site-packages/redis/client.py", line 3503, in parse_response
    if not block and not conn.can_read(timeout=timeout):
  File "/home/gitonga/frappe-bench/env/lib/python3.8/site-packages/redis/connection.py", line 734, in can_read
    if not block and not conn.can_read(timeout=timeout):
  File "/home/gitonga/frappe-bench/env/lib/python3.8/site-packages/redis/connection.py", line 734, in can_read
    return self._parser.can_read(timeout)
  File "/home/gitonga/frappe-bench/env/lib/python3.8/site-packages/redis/connection.py", line 321, in can_read
    return self._parser.can_read(timeout)
  File "/home/gitonga/frappe-bench/env/lib/python3.8/site-packages/redis/connection.py", line 321, in can_read
    return self._buffer and self._buffer.can_read(timeout)
  File "/home/gitonga/frappe-bench/env/lib/python3.8/site-packages/redis/connection.py", line 230, in can_read
    return self._buffer and self._buffer.can_read(timeout)
  File "/home/gitonga/frappe-bench/env/lib/python3.8/site-packages/redis/connection.py", line 230, in can_read
    self._read_from_socket(timeout=timeout,
  File "/home/gitonga/frappe-bench/env/lib/python3.8/site-packages/redis/connection.py", line 201, in _read_from_socket
    self._read_from_socket(timeout=timeout,
  File "/home/gitonga/frappe-bench/env/lib/python3.8/site-packages/redis/connection.py", line 201, in _read_from_socket
    raise ConnectionError(SERVER_CLOSED_CONNECTION_ERROR)
redis.exceptions.ConnectionError: Connection closed by server.
    raise ConnectionError(SERVER_CLOSED_CONNECTION_ERROR)
    if not block and not conn.can_read(timeout=timeout):
  File "/home/gitonga/frappe-bench/env/lib/python3.8/site-packages/redis/connection.py", line 734, in can_read
    return self._parser.can_read(timeout)
  File "/home/gitonga/frappe-bench/env/lib/python3.8/site-packages/redis/connection.py", line 321, in can_read
    return self._buffer and self._buffer.can_read(timeout)
  File "/home/gitonga/frappe-bench/env/lib/python3.8/site-packages/redis/connection.py", line 230, in can_read
    self._read_from_socket(timeout=timeout,
  File "/home/gitonga/frappe-bench/env/lib/python3.8/site-packages/redis/connection.py", line 201, in _read_from_socket
    raise ConnectionError(SERVER_CLOSED_CONNECTION_ERROR)
redis.exceptions.ConnectionError: Connection closed by server.
redis.exceptions.ConnectionError: Connection closed by server.
